[23/Mar/2017 16:05:28] ERROR [django.request:256] Internal Server Error: /services/
Traceback (most recent call last):
  File "/usr/local/lib/python2.7/dist-packages/django/core/handlers/base.py", line 132, in get_response
    response = wrapped_callback(request, *callback_args, **callback_kwargs)
  File "/usr/local/lib/python2.7/dist-packages/django/views/generic/base.py", line 71, in view
    return self.dispatch(request, *args, **kwargs)
  File "/usr/local/lib/python2.7/dist-packages/django/utils/decorators.py", line 34, in _wrapper
    return bound_func(*args, **kwargs)
  File "/usr/local/lib/python2.7/dist-packages/django/contrib/auth/decorators.py", line 22, in _wrapped_view
    return view_func(request, *args, **kwargs)
  File "/usr/local/lib/python2.7/dist-packages/django/utils/decorators.py", line 30, in bound_func
    return func.__get__(self, type(self))(*args2, **kwargs2)
  File "/home/picasso/git/export/export/nutep/views.py", line 58, in dispatch
    return super(BaseView, self).dispatch(*args, **kwargs)
  File "/usr/local/lib/python2.7/dist-packages/django/views/generic/base.py", line 89, in dispatch
    return handler(request, *args, **kwargs)
  File "/usr/local/lib/python2.7/dist-packages/django/views/generic/base.py", line 158, in get
    context = self.get_context_data(**kwargs)
  File "/home/picasso/git/export/export/nutep/views.py", line 72, in get_context_data
    context = super(ServiceView, self).get_context_data(**kwargs)
  File "/home/picasso/git/export/export/nutep/views.py", line 61, in get_context_data
    vessels = Vessel.objects.filter(history__user__profile__lines__in=self.request.user.get_profile().lines.all()).distinct()
  File "/usr/local/lib/python2.7/dist-packages/django/utils/functional.py", line 226, in inner
    return func(self._wrapped, *args)
AttributeError: 'User' object has no attribute 'get_profile'
[23/Mar/2017 16:14:54] ERROR [django.request:256] Internal Server Error: /services/
Traceback (most recent call last):
  File "/usr/local/lib/python2.7/dist-packages/django/core/handlers/base.py", line 164, in get_response
    response = response.render()
  File "/usr/local/lib/python2.7/dist-packages/django/template/response.py", line 158, in render
    self.content = self.rendered_content
  File "/usr/local/lib/python2.7/dist-packages/django/template/response.py", line 133, in rendered_content
    template = self._resolve_template(self.template_name)
  File "/usr/local/lib/python2.7/dist-packages/django/template/response.py", line 88, in _resolve_template
    new_template = self.resolve_template(template)
  File "/usr/local/lib/python2.7/dist-packages/django/template/response.py", line 78, in resolve_template
    return loader.select_template(template, using=self.using)
  File "/usr/local/lib/python2.7/dist-packages/django/template/loader.py", line 64, in select_template
    return engine.get_template(template_name, dirs)
  File "/usr/local/lib/python2.7/dist-packages/django/template/backends/django.py", line 30, in get_template
    return Template(self.engine.get_template(template_name, dirs))
  File "/usr/local/lib/python2.7/dist-packages/django/template/engine.py", line 167, in get_template
    template, origin = self.find_template(template_name, dirs)
  File "/usr/local/lib/python2.7/dist-packages/django/template/engine.py", line 141, in find_template
    source, display_name = loader(name, dirs)
  File "/usr/local/lib/python2.7/dist-packages/django/template/loaders/base.py", line 13, in __call__
    return self.load_template(template_name, template_dirs)
  File "/usr/local/lib/python2.7/dist-packages/django/template/loaders/base.py", line 23, in load_template
    template = Template(source, origin, template_name, self.engine)
  File "/usr/local/lib/python2.7/dist-packages/django/template/base.py", line 191, in __init__
    self.nodelist = engine.compile_string(template_string, origin)
  File "/usr/local/lib/python2.7/dist-packages/django/template/engine.py", line 261, in compile_string
    return parser.parse()
  File "/usr/local/lib/python2.7/dist-packages/django/template/base.py", line 342, in parse
    compiled_result = compile_func(self, token)
  File "/usr/local/lib/python2.7/dist-packages/django/template/defaulttags.py", line 872, in do_for
    nodelist_loop = parser.parse(('empty', 'endfor',))
  File "/usr/local/lib/python2.7/dist-packages/django/template/base.py", line 342, in parse
    compiled_result = compile_func(self, token)
  File "/usr/local/lib/python2.7/dist-packages/django/template/defaulttags.py", line 872, in do_for
    nodelist_loop = parser.parse(('empty', 'endfor',))
  File "/usr/local/lib/python2.7/dist-packages/django/template/base.py", line 342, in parse
    compiled_result = compile_func(self, token)
  File "/usr/local/lib/python2.7/dist-packages/django/template/defaulttags.py", line 872, in do_for
    nodelist_loop = parser.parse(('empty', 'endfor',))
  File "/usr/local/lib/python2.7/dist-packages/django/template/base.py", line 342, in parse
    compiled_result = compile_func(self, token)
  File "/usr/local/lib/python2.7/dist-packages/django/template/defaulttags.py", line 1440, in url
    viewname = parser.compile_filter(bits[1])
  File "/usr/local/lib/python2.7/dist-packages/django/template/base.py", line 424, in compile_filter
    return FilterExpression(token, self)
  File "/usr/local/lib/python2.7/dist-packages/django/template/base.py", line 640, in __init__
    "from '%s'" % (token[upto:], token))
TemplateSyntaxError: Could not parse the remainder: '-details' from 'template-details'
[23/Mar/2017 17:02:17] ERROR [django.request:256] Internal Server Error: /services/
Traceback (most recent call last):
  File "/usr/local/lib/python2.7/dist-packages/django/core/handlers/base.py", line 164, in get_response
    response = response.render()
  File "/usr/local/lib/python2.7/dist-packages/django/template/response.py", line 158, in render
    self.content = self.rendered_content
  File "/usr/local/lib/python2.7/dist-packages/django/template/response.py", line 135, in rendered_content
    content = template.render(context, self._request)
  File "/usr/local/lib/python2.7/dist-packages/django/template/backends/django.py", line 74, in render
    return self.template.render(context)
  File "/usr/local/lib/python2.7/dist-packages/django/template/base.py", line 210, in render
    return self._render(context)
  File "/usr/local/lib/python2.7/dist-packages/django/template/base.py", line 202, in _render
    return self.nodelist.render(context)
  File "/usr/local/lib/python2.7/dist-packages/django/template/base.py", line 905, in render
    bit = self.render_node(node, context)
  File "/usr/local/lib/python2.7/dist-packages/django/template/debug.py", line 79, in render_node
    return node.render(context)
  File "/usr/local/lib/python2.7/dist-packages/django/template/loader_tags.py", line 56, in render
    result = self.nodelist.render(context)
  File "/usr/local/lib/python2.7/dist-packages/django/template/base.py", line 905, in render
    bit = self.render_node(node, context)
  File "/usr/local/lib/python2.7/dist-packages/django/template/debug.py", line 79, in render_node
    return node.render(context)
  File "/usr/local/lib/python2.7/dist-packages/django/template/debug.py", line 92, in render
    output = force_text(output)
  File "/usr/local/lib/python2.7/dist-packages/django/utils/encoding.py", line 92, in force_text
    s = six.text_type(s)
  File "/usr/local/lib/python2.7/dist-packages/django/utils/html.py", line 390, in <lambda>
    klass.__unicode__ = lambda self: mark_safe(klass_unicode(self))
  File "/usr/local/lib/python2.7/dist-packages/django/forms/forms.py", line 143, in __str__
    return self.as_table()
  File "/usr/local/lib/python2.7/dist-packages/django/forms/forms.py", line 284, in as_table
    errors_on_separate_row=False)
  File "/usr/local/lib/python2.7/dist-packages/django/forms/forms.py", line 241, in _html_output
    'field': six.text_type(bf),
  File "/usr/local/lib/python2.7/dist-packages/django/utils/html.py", line 390, in <lambda>
    klass.__unicode__ = lambda self: mark_safe(klass_unicode(self))
  File "/usr/local/lib/python2.7/dist-packages/django/forms/forms.py", line 537, in __str__
    return self.as_widget()
  File "/usr/local/lib/python2.7/dist-packages/django/forms/forms.py", line 593, in as_widget
    return force_text(widget.render(name, self.value(), attrs=attrs))
  File "/usr/local/lib/python2.7/dist-packages/django_select2/forms.py", line 219, in render
    self.set_to_cache()
  File "/usr/local/lib/python2.7/dist-packages/django_select2/forms.py", line 341, in set_to_cache
    queryset = self.get_queryset()
  File "/usr/local/lib/python2.7/dist-packages/django_select2/forms.py", line 387, in get_queryset
    queryset = self.model._default_manager.all()
AttributeError: 'QuerySet' object has no attribute '_default_manager'
[23/Mar/2017 17:07:53] ERROR [django.request:256] Internal Server Error: /services/
Traceback (most recent call last):
  File "/usr/local/lib/python2.7/dist-packages/django/core/handlers/base.py", line 119, in get_response
    resolver_match = resolver.resolve(request.path_info)
  File "/usr/local/lib/python2.7/dist-packages/django/core/urlresolvers.py", line 365, in resolve
    for pattern in self.url_patterns:
  File "/usr/local/lib/python2.7/dist-packages/django/core/urlresolvers.py", line 401, in url_patterns
    patterns = getattr(self.urlconf_module, "urlpatterns", self.urlconf_module)
  File "/usr/local/lib/python2.7/dist-packages/django/core/urlresolvers.py", line 395, in urlconf_module
    self._urlconf_module = import_module(self.urlconf_name)
  File "/usr/lib/python2.7/importlib/__init__.py", line 37, in import_module
    __import__(name)
  File "/home/picasso/git/export/export/export/urls.py", line 6, in <module>
    from nutep.views import landing, upload_file, TemplateDeleteView,\
  File "/home/picasso/git/export/export/nutep/views.py", line 10, in <module>
    from nutep.forms import TemplateForm
  File "/home/picasso/git/export/export/nutep/forms.py", line 18, in <module>
    class TemplateForm(ModelForm):
  File "/home/picasso/git/export/export/nutep/forms.py", line 19, in TemplateForm
    contract = forms.ModelChoiceField(widget=ContractCustomWidget())
TypeError: __init__() takes at least 2 arguments (2 given)
[23/Mar/2017 17:32:56] ERROR [django.request:256] Internal Server Error: /services/
Traceback (most recent call last):
  File "/usr/local/lib/python2.7/dist-packages/django/core/handlers/base.py", line 132, in get_response
    response = wrapped_callback(request, *callback_args, **callback_kwargs)
  File "/usr/local/lib/python2.7/dist-packages/django/views/generic/base.py", line 71, in view
    return self.dispatch(request, *args, **kwargs)
  File "/usr/local/lib/python2.7/dist-packages/django/utils/decorators.py", line 34, in _wrapper
    return bound_func(*args, **kwargs)
  File "/usr/local/lib/python2.7/dist-packages/django/contrib/auth/decorators.py", line 22, in _wrapped_view
    return view_func(request, *args, **kwargs)
  File "/usr/local/lib/python2.7/dist-packages/django/utils/decorators.py", line 30, in bound_func
    return func.__get__(self, type(self))(*args2, **kwargs2)
  File "/home/picasso/git/export/export/nutep/views.py", line 58, in dispatch
    return super(BaseView, self).dispatch(*args, **kwargs)
  File "/usr/local/lib/python2.7/dist-packages/django/views/generic/base.py", line 89, in dispatch
    return handler(request, *args, **kwargs)
  File "/usr/local/lib/python2.7/dist-packages/django/views/generic/base.py", line 158, in get
    context = self.get_context_data(**kwargs)
  File "/home/picasso/git/export/export/nutep/views.py", line 87, in get_context_data
    template_form.fields['contract'].queryset = Contract.objects.filter(lines__in=self.request.user.profile.lines.all())
  File "/usr/local/lib/python2.7/dist-packages/django/db/models/manager.py", line 127, in manager_method
    return getattr(self.get_queryset(), name)(*args, **kwargs)
  File "/usr/local/lib/python2.7/dist-packages/django/db/models/query.py", line 679, in filter
    return self._filter_or_exclude(False, *args, **kwargs)
  File "/usr/local/lib/python2.7/dist-packages/django/db/models/query.py", line 697, in _filter_or_exclude
    clone.query.add_q(Q(*args, **kwargs))
  File "/usr/local/lib/python2.7/dist-packages/django/db/models/sql/query.py", line 1310, in add_q
    clause, require_inner = self._add_q(where_part, self.used_aliases)
  File "/usr/local/lib/python2.7/dist-packages/django/db/models/sql/query.py", line 1338, in _add_q
    allow_joins=allow_joins, split_subq=split_subq,
  File "/usr/local/lib/python2.7/dist-packages/django/db/models/sql/query.py", line 1150, in build_filter
    lookups, parts, reffed_expression = self.solve_lookup_type(arg)
  File "/usr/local/lib/python2.7/dist-packages/django/db/models/sql/query.py", line 1036, in solve_lookup_type
    _, field, _, lookup_parts = self.names_to_path(lookup_splitted, self.get_meta())
  File "/usr/local/lib/python2.7/dist-packages/django/db/models/sql/query.py", line 1397, in names_to_path
    "Choices are: %s" % (name, ", ".join(available)))
FieldError: Cannot resolve keyword 'lines' into field. Choices are: deleted, expired, guid, id, line, line_id, name, startdate, terminal, terminal_id, uploadedtemplate
[23/Mar/2017 17:35:08] ERROR [django.request:256] Internal Server Error: /services/
Traceback (most recent call last):
  File "/usr/local/lib/python2.7/dist-packages/django/core/handlers/base.py", line 132, in get_response
    response = wrapped_callback(request, *callback_args, **callback_kwargs)
  File "/usr/local/lib/python2.7/dist-packages/django/views/generic/base.py", line 71, in view
    return self.dispatch(request, *args, **kwargs)
  File "/usr/local/lib/python2.7/dist-packages/django/utils/decorators.py", line 34, in _wrapper
    return bound_func(*args, **kwargs)
  File "/usr/local/lib/python2.7/dist-packages/django/contrib/auth/decorators.py", line 22, in _wrapped_view
    return view_func(request, *args, **kwargs)
  File "/usr/local/lib/python2.7/dist-packages/django/utils/decorators.py", line 30, in bound_func
    return func.__get__(self, type(self))(*args2, **kwargs2)
  File "/home/picasso/git/export/export/nutep/views.py", line 58, in dispatch
    return super(BaseView, self).dispatch(*args, **kwargs)
  File "/usr/local/lib/python2.7/dist-packages/django/views/generic/base.py", line 89, in dispatch
    return handler(request, *args, **kwargs)
  File "/usr/local/lib/python2.7/dist-packages/django/views/generic/base.py", line 158, in get
    context = self.get_context_data(**kwargs)
  File "/home/picasso/git/export/export/nutep/views.py", line 87, in get_context_data
    template_form.fields['contract'].queryset = Contract.objects.filter(line__not__in=self.request.user.profile.lines.all())
  File "/usr/local/lib/python2.7/dist-packages/django/db/models/manager.py", line 127, in manager_method
    return getattr(self.get_queryset(), name)(*args, **kwargs)
  File "/usr/local/lib/python2.7/dist-packages/django/db/models/query.py", line 679, in filter
    return self._filter_or_exclude(False, *args, **kwargs)
  File "/usr/local/lib/python2.7/dist-packages/django/db/models/query.py", line 697, in _filter_or_exclude
    clone.query.add_q(Q(*args, **kwargs))
  File "/usr/local/lib/python2.7/dist-packages/django/db/models/sql/query.py", line 1310, in add_q
    clause, require_inner = self._add_q(where_part, self.used_aliases)
  File "/usr/local/lib/python2.7/dist-packages/django/db/models/sql/query.py", line 1338, in _add_q
    allow_joins=allow_joins, split_subq=split_subq,
  File "/usr/local/lib/python2.7/dist-packages/django/db/models/sql/query.py", line 1200, in build_filter
    lookups, value)
  File "/usr/local/lib/python2.7/dist-packages/django/db/models/fields/related.py", line 1727, in get_lookup_constraint
    raise exceptions.FieldError('Relation fields do not support nested lookups')
FieldError: Relation fields do not support nested lookups
