[03/Mar/2017 16:50:33] ERROR [django.request:213] Internal Server Error: /gettemplate/32
Traceback (most recent call last):
  File "/usr/local/lib/python2.7/dist-packages/django/core/handlers/base.py", line 109, in get_response
    response = callback(request, *callback_args, **callback_kwargs)
  File "/usr/local/lib/python2.7/dist-packages/django/contrib/auth/decorators.py", line 20, in _wrapped_view
    return view_func(request, *args, **kwargs)
  File "/home/picasso/git/export/export/nutep/views.py", line 88, in get_template_status
    draft_service = DraftService(WEB_SERVISES['draft'])
  File "/home/picasso/git/export/export/nutep/services.py", line 12, in __init__
    self.set_client(settings)
  File "/home/picasso/git/export/export/nutep/services.py", line 22, in set_client
    self._client = Client(self.url, headers=authenticationHeader, cache=NoCache())
  File "/usr/local/lib/python2.7/dist-packages/suds/client.py", line 112, in __init__
    self.wsdl = reader.open(url)
  File "/usr/local/lib/python2.7/dist-packages/suds/reader.py", line 152, in open
    d = self.fn(url, self.options)
  File "/usr/local/lib/python2.7/dist-packages/suds/wsdl.py", line 136, in __init__
    d = reader.open(url)
  File "/usr/local/lib/python2.7/dist-packages/suds/reader.py", line 79, in open
    d = self.download(url)
  File "/usr/local/lib/python2.7/dist-packages/suds/reader.py", line 95, in download
    fp = self.options.transport.open(Request(url))
  File "/usr/local/lib/python2.7/dist-packages/suds/transport/https.py", line 60, in open
    return  HttpTransport.open(self, request)
  File "/usr/local/lib/python2.7/dist-packages/suds/transport/http.py", line 64, in open
    raise TransportError(str(e), e.code, e.fp)
TransportError: HTTP Error 500: Internal server error
[03/Mar/2017 16:50:34] ERROR [django.request:213] Internal Server Error: /gettemplate/32
Traceback (most recent call last):
  File "/usr/local/lib/python2.7/dist-packages/django/core/handlers/base.py", line 109, in get_response
    response = callback(request, *callback_args, **callback_kwargs)
  File "/usr/local/lib/python2.7/dist-packages/django/contrib/auth/decorators.py", line 20, in _wrapped_view
    return view_func(request, *args, **kwargs)
  File "/home/picasso/git/export/export/nutep/views.py", line 88, in get_template_status
    draft_service = DraftService(WEB_SERVISES['draft'])
  File "/home/picasso/git/export/export/nutep/services.py", line 12, in __init__
    self.set_client(settings)
  File "/home/picasso/git/export/export/nutep/services.py", line 22, in set_client
    self._client = Client(self.url, headers=authenticationHeader, cache=NoCache())
  File "/usr/local/lib/python2.7/dist-packages/suds/client.py", line 112, in __init__
    self.wsdl = reader.open(url)
  File "/usr/local/lib/python2.7/dist-packages/suds/reader.py", line 152, in open
    d = self.fn(url, self.options)
  File "/usr/local/lib/python2.7/dist-packages/suds/wsdl.py", line 136, in __init__
    d = reader.open(url)
  File "/usr/local/lib/python2.7/dist-packages/suds/reader.py", line 79, in open
    d = self.download(url)
  File "/usr/local/lib/python2.7/dist-packages/suds/reader.py", line 95, in download
    fp = self.options.transport.open(Request(url))
  File "/usr/local/lib/python2.7/dist-packages/suds/transport/https.py", line 60, in open
    return  HttpTransport.open(self, request)
  File "/usr/local/lib/python2.7/dist-packages/suds/transport/http.py", line 64, in open
    raise TransportError(str(e), e.code, e.fp)
TransportError: HTTP Error 500: Internal server error
[03/Mar/2017 16:50:35] ERROR [django.request:213] Internal Server Error: /gettemplate/32
Traceback (most recent call last):
  File "/usr/local/lib/python2.7/dist-packages/django/core/handlers/base.py", line 109, in get_response
    response = callback(request, *callback_args, **callback_kwargs)
  File "/usr/local/lib/python2.7/dist-packages/django/contrib/auth/decorators.py", line 20, in _wrapped_view
    return view_func(request, *args, **kwargs)
  File "/home/picasso/git/export/export/nutep/views.py", line 88, in get_template_status
    draft_service = DraftService(WEB_SERVISES['draft'])
  File "/home/picasso/git/export/export/nutep/services.py", line 12, in __init__
    self.set_client(settings)
  File "/home/picasso/git/export/export/nutep/services.py", line 22, in set_client
    self._client = Client(self.url, headers=authenticationHeader, cache=NoCache())
  File "/usr/local/lib/python2.7/dist-packages/suds/client.py", line 112, in __init__
    self.wsdl = reader.open(url)
  File "/usr/local/lib/python2.7/dist-packages/suds/reader.py", line 152, in open
    d = self.fn(url, self.options)
  File "/usr/local/lib/python2.7/dist-packages/suds/wsdl.py", line 136, in __init__
    d = reader.open(url)
  File "/usr/local/lib/python2.7/dist-packages/suds/reader.py", line 79, in open
    d = self.download(url)
  File "/usr/local/lib/python2.7/dist-packages/suds/reader.py", line 95, in download
    fp = self.options.transport.open(Request(url))
  File "/usr/local/lib/python2.7/dist-packages/suds/transport/https.py", line 60, in open
    return  HttpTransport.open(self, request)
  File "/usr/local/lib/python2.7/dist-packages/suds/transport/http.py", line 64, in open
    raise TransportError(str(e), e.code, e.fp)
TransportError: HTTP Error 500: Internal server error
[03/Mar/2017 16:55:09] ERROR [django.request:213] Internal Server Error: /gettemplate/32
Traceback (most recent call last):
  File "/usr/local/lib/python2.7/dist-packages/django/core/handlers/base.py", line 109, in get_response
    response = callback(request, *callback_args, **callback_kwargs)
  File "/usr/local/lib/python2.7/dist-packages/django/contrib/auth/decorators.py", line 20, in _wrapped_view
    return view_func(request, *args, **kwargs)
  File "/home/picasso/git/export/export/nutep/views.py", line 90, in get_template_status
    status = draft_service.update_status(pk)
  File "/home/picasso/git/export/export/nutep/services.py", line 65, in update_status
    template.contract = self.get_contract(response.xml_contract)
AttributeError: Data instance has no attribute 'xml_contract'
[03/Mar/2017 16:55:40] ERROR [django.request:213] Internal Server Error: /gettemplate/32
Traceback (most recent call last):
  File "/usr/local/lib/python2.7/dist-packages/django/core/handlers/base.py", line 109, in get_response
    response = callback(request, *callback_args, **callback_kwargs)
  File "/usr/local/lib/python2.7/dist-packages/django/contrib/auth/decorators.py", line 20, in _wrapped_view
    return view_func(request, *args, **kwargs)
  File "/home/picasso/git/export/export/nutep/views.py", line 90, in get_template_status
    status = draft_service.update_status(pk)
  File "/home/picasso/git/export/export/nutep/services.py", line 65, in update_status
    template.contract = self.get_contract(response.contract)
  File "/usr/local/lib/python2.7/dist-packages/django/db/models/fields/related.py", line 366, in __set__
    self.field.name, self.field.rel.to._meta.object_name))
ValueError: Cannot assign "<Vessel: COSCO-10-2012>": "UploadedTemplate.contract" must be a "Contract" instance.
[03/Mar/2017 16:56:50] ERROR [django.request:213] Internal Server Error: /gettemplate/32
Traceback (most recent call last):
  File "/usr/local/lib/python2.7/dist-packages/django/core/handlers/base.py", line 109, in get_response
    response = callback(request, *callback_args, **callback_kwargs)
  File "/usr/local/lib/python2.7/dist-packages/django/contrib/auth/decorators.py", line 20, in _wrapped_view
    return view_func(request, *args, **kwargs)
  File "/home/picasso/git/export/export/nutep/views.py", line 90, in get_template_status
    status = draft_service.update_status(pk)
  File "/home/picasso/git/export/export/nutep/services.py", line 66, in update_status
    template.contract = self.get_contract(response.contract)
  File "/home/picasso/git/export/export/nutep/services.py", line 54, in get_contract
    contract, created = Contract.objects.get_or_create(guid=xml_contract.guid,)  # @UnusedVariable
  File "/usr/local/lib/python2.7/dist-packages/django/db/models/manager.py", line 134, in get_or_create
    return self.get_query_set().get_or_create(**kwargs)
  File "/usr/local/lib/python2.7/dist-packages/django/db/models/query.py", line 452, in get_or_create
    obj.save(force_insert=True, using=self.db)
  File "/usr/local/lib/python2.7/dist-packages/django/db/models/base.py", line 463, in save
    self.save_base(using=using, force_insert=force_insert, force_update=force_update)
  File "/usr/local/lib/python2.7/dist-packages/django/db/models/base.py", line 551, in save_base
    result = manager._insert([self], fields=fields, return_id=update_pk, using=using, raw=raw)
  File "/usr/local/lib/python2.7/dist-packages/django/db/models/manager.py", line 203, in _insert
    return insert_query(self.model, objs, fields, **kwargs)
  File "/usr/local/lib/python2.7/dist-packages/django/db/models/query.py", line 1593, in insert_query
    return query.get_compiler(using=using).execute_sql(return_id)
  File "/usr/local/lib/python2.7/dist-packages/django/db/models/sql/compiler.py", line 912, in execute_sql
    cursor.execute(sql, params)
  File "/usr/local/lib/python2.7/dist-packages/django/db/backends/util.py", line 40, in execute
    return self.cursor.execute(sql, params)
  File "/usr/local/lib/python2.7/dist-packages/django/db/backends/postgresql_psycopg2/base.py", line 52, in execute
    return self.cursor.execute(query, args)
IntegrityError: null value in column "line_id" violates not-null constraint

[04/Mar/2017 18:52:33] ERROR [django.request:213] Internal Server Error: /templatedetails/32
Traceback (most recent call last):
  File "/usr/local/lib/python2.7/dist-packages/django/core/handlers/base.py", line 134, in get_response
    response = response.render()
  File "/usr/local/lib/python2.7/dist-packages/django/template/response.py", line 104, in render
    self._set_content(self.rendered_content)
  File "/usr/local/lib/python2.7/dist-packages/django/template/response.py", line 79, in rendered_content
    template = self.resolve_template(self.template_name)
  File "/usr/local/lib/python2.7/dist-packages/django/template/response.py", line 55, in resolve_template
    return loader.select_template(template)
  File "/usr/local/lib/python2.7/dist-packages/django/template/loader.py", line 193, in select_template
    raise TemplateDoesNotExist(', '.join(not_found))
TemplateDoesNotExist: template_detail.html
[04/Mar/2017 18:52:56] ERROR [django.request:213] Internal Server Error: /templatedetails/32
Traceback (most recent call last):
  File "/usr/local/lib/python2.7/dist-packages/django/core/handlers/base.py", line 134, in get_response
    response = response.render()
  File "/usr/local/lib/python2.7/dist-packages/django/template/response.py", line 104, in render
    self._set_content(self.rendered_content)
  File "/usr/local/lib/python2.7/dist-packages/django/template/response.py", line 79, in rendered_content
    template = self.resolve_template(self.template_name)
  File "/usr/local/lib/python2.7/dist-packages/django/template/response.py", line 55, in resolve_template
    return loader.select_template(template)
  File "/usr/local/lib/python2.7/dist-packages/django/template/loader.py", line 187, in select_template
    return get_template(template_name)
  File "/usr/local/lib/python2.7/dist-packages/django/template/loader.py", line 145, in get_template
    template, origin = find_template(template_name)
  File "/usr/local/lib/python2.7/dist-packages/django/template/loader.py", line 134, in find_template
    source, display_name = loader(name, dirs)
  File "/usr/local/lib/python2.7/dist-packages/django/template/loader.py", line 42, in __call__
    return self.load_template(template_name, template_dirs)
  File "/usr/local/lib/python2.7/dist-packages/django/template/loader.py", line 48, in load_template
    template = get_template_from_string(source, origin, template_name)
  File "/usr/local/lib/python2.7/dist-packages/django/template/loader.py", line 156, in get_template_from_string
    return Template(source, origin, name)
  File "/usr/local/lib/python2.7/dist-packages/django/template/base.py", line 125, in __init__
    self.nodelist = compile_string(template_string, origin)
  File "/usr/local/lib/python2.7/dist-packages/django/template/base.py", line 153, in compile_string
    return parser.parse()
  File "/usr/local/lib/python2.7/dist-packages/django/template/base.py", line 265, in parse
    self.invalid_block_tag(token, command, parse_until)
  File "/usr/local/lib/python2.7/dist-packages/django/template/base.py", line 321, in invalid_block_tag
    raise self.error(token, "Invalid block tag: '%s'" % command)
TemplateSyntaxError: Invalid block tag: 'extend'
[04/Mar/2017 20:12:05] ERROR [django.request:213] Internal Server Error: /templatedetails/32
Traceback (most recent call last):
  File "/usr/local/lib/python2.7/dist-packages/django/core/handlers/base.py", line 134, in get_response
    response = response.render()
  File "/usr/local/lib/python2.7/dist-packages/django/template/response.py", line 104, in render
    self._set_content(self.rendered_content)
  File "/usr/local/lib/python2.7/dist-packages/django/template/response.py", line 79, in rendered_content
    template = self.resolve_template(self.template_name)
  File "/usr/local/lib/python2.7/dist-packages/django/template/response.py", line 55, in resolve_template
    return loader.select_template(template)
  File "/usr/local/lib/python2.7/dist-packages/django/template/loader.py", line 187, in select_template
    return get_template(template_name)
  File "/usr/local/lib/python2.7/dist-packages/django/template/loader.py", line 145, in get_template
    template, origin = find_template(template_name)
  File "/usr/local/lib/python2.7/dist-packages/django/template/loader.py", line 134, in find_template
    source, display_name = loader(name, dirs)
  File "/usr/local/lib/python2.7/dist-packages/django/template/loader.py", line 42, in __call__
    return self.load_template(template_name, template_dirs)
  File "/usr/local/lib/python2.7/dist-packages/django/template/loader.py", line 48, in load_template
    template = get_template_from_string(source, origin, template_name)
  File "/usr/local/lib/python2.7/dist-packages/django/template/loader.py", line 156, in get_template_from_string
    return Template(source, origin, name)
  File "/usr/local/lib/python2.7/dist-packages/django/template/base.py", line 125, in __init__
    self.nodelist = compile_string(template_string, origin)
  File "/usr/local/lib/python2.7/dist-packages/django/template/base.py", line 153, in compile_string
    return parser.parse()
  File "/usr/local/lib/python2.7/dist-packages/django/template/base.py", line 267, in parse
    compiled_result = compile_func(self, token)
  File "/usr/local/lib/python2.7/dist-packages/django/template/loader_tags.py", line 214, in do_extends
    nodelist = parser.parse()
  File "/usr/local/lib/python2.7/dist-packages/django/template/base.py", line 267, in parse
    compiled_result = compile_func(self, token)
  File "/usr/local/lib/python2.7/dist-packages/django/template/loader_tags.py", line 189, in do_block
    nodelist = parser.parse(('endblock',))
  File "/usr/local/lib/python2.7/dist-packages/django/template/base.py", line 267, in parse
    compiled_result = compile_func(self, token)
  File "/usr/local/lib/python2.7/dist-packages/django/template/defaulttags.py", line 900, in do_if
    nodelist = parser.parse(('elif', 'else', 'endif'))
  File "/usr/local/lib/python2.7/dist-packages/django/template/base.py", line 265, in parse
    self.invalid_block_tag(token, command, parse_until)
  File "/usr/local/lib/python2.7/dist-packages/django/template/base.py", line 320, in invalid_block_tag
    (command, get_text_list(["'%s'" % p for p in parse_until])))
TemplateSyntaxError: Invalid block tag: 'bootstrap_paginator', expected 'elif','else' \u0438\u043b\u0438 'endif'
