[07/Mar/2017 16:33:24] ERROR [django.request:213] Internal Server Error: /templatedetails/34
Traceback (most recent call last):
  File "/usr/local/lib/python2.7/dist-packages/django/core/handlers/base.py", line 134, in get_response
    response = response.render()
  File "/usr/local/lib/python2.7/dist-packages/django/template/response.py", line 104, in render
    self._set_content(self.rendered_content)
  File "/usr/local/lib/python2.7/dist-packages/django/template/response.py", line 81, in rendered_content
    content = template.render(context)
  File "/usr/local/lib/python2.7/dist-packages/django/template/base.py", line 140, in render
    return self._render(context)
  File "/usr/local/lib/python2.7/dist-packages/django/template/base.py", line 134, in _render
    return self.nodelist.render(context)
  File "/usr/local/lib/python2.7/dist-packages/django/template/base.py", line 823, in render
    bit = self.render_node(node, context)
  File "/usr/local/lib/python2.7/dist-packages/django/template/debug.py", line 74, in render_node
    return node.render(context)
  File "/usr/local/lib/python2.7/dist-packages/django/template/loader_tags.py", line 123, in render
    return compiled_parent._render(context)
  File "/usr/local/lib/python2.7/dist-packages/django/template/base.py", line 134, in _render
    return self.nodelist.render(context)
  File "/usr/local/lib/python2.7/dist-packages/django/template/base.py", line 823, in render
    bit = self.render_node(node, context)
  File "/usr/local/lib/python2.7/dist-packages/django/template/debug.py", line 74, in render_node
    return node.render(context)
  File "/usr/local/lib/python2.7/dist-packages/django/template/loader_tags.py", line 62, in render
    result = block.nodelist.render(context)
  File "/usr/local/lib/python2.7/dist-packages/django/template/base.py", line 823, in render
    bit = self.render_node(node, context)
  File "/usr/local/lib/python2.7/dist-packages/django/template/debug.py", line 74, in render_node
    return node.render(context)
  File "/usr/local/lib/python2.7/dist-packages/django/template/debug.py", line 84, in render
    output = self.filter_expression.resolve(context)
  File "/usr/local/lib/python2.7/dist-packages/django/template/base.py", line 571, in resolve
    obj = self.var.resolve(context)
  File "/usr/local/lib/python2.7/dist-packages/django/template/base.py", line 721, in resolve
    value = self._resolve_lookup(context)
  File "/usr/local/lib/python2.7/dist-packages/django/template/base.py", line 772, in _resolve_lookup
    current = current()
  File "/home/picasso/git/export/export/nutep/models.py", line 228, in drafts_readiness
    return int(done / total * 100)
ZeroDivisionError: float division by zero
[09/Mar/2017 17:16:26] ERROR [django.request:213] Internal Server Error: /upload/
Traceback (most recent call last):
  File "/usr/local/lib/python2.7/dist-packages/django/core/handlers/base.py", line 109, in get_response
    response = callback(request, *callback_args, **callback_kwargs)
  File "/usr/local/lib/python2.7/dist-packages/django/contrib/auth/decorators.py", line 20, in _wrapped_view
    return view_func(request, *args, **kwargs)
  File "/home/picasso/git/export/export/nutep/views.py", line 214, in upload_file
    draft_service = DraftService(WEB_SERVISES['draft'])
  File "/home/picasso/git/export/export/nutep/services.py", line 15, in __init__
    self.set_client(settings)
  File "/home/picasso/git/export/export/nutep/services.py", line 25, in set_client
    self._client = Client(self.url, headers=authenticationHeader, cache=NoCache())
  File "/usr/local/lib/python2.7/dist-packages/suds/client.py", line 112, in __init__
    self.wsdl = reader.open(url)
  File "/usr/local/lib/python2.7/dist-packages/suds/reader.py", line 152, in open
    d = self.fn(url, self.options)
  File "/usr/local/lib/python2.7/dist-packages/suds/wsdl.py", line 136, in __init__
    d = reader.open(url)
  File "/usr/local/lib/python2.7/dist-packages/suds/reader.py", line 79, in open
    d = self.download(url)
  File "/usr/local/lib/python2.7/dist-packages/suds/reader.py", line 95, in download
    fp = self.options.transport.open(Request(url))
  File "/usr/local/lib/python2.7/dist-packages/suds/transport/https.py", line 60, in open
    return  HttpTransport.open(self, request)
  File "/usr/local/lib/python2.7/dist-packages/suds/transport/http.py", line 64, in open
    raise TransportError(str(e), e.code, e.fp)
TransportError: HTTP Error 500: Internal server error
[17/Mar/2017 11:00:19] ERROR [django.request:213] Internal Server Error: /templatedetails/34
Traceback (most recent call last):
  File "/usr/local/lib/python2.7/dist-packages/django/core/handlers/base.py", line 109, in get_response
    response = callback(request, *callback_args, **callback_kwargs)
  File "/usr/local/lib/python2.7/dist-packages/django/views/generic/base.py", line 48, in view
    return self.dispatch(request, *args, **kwargs)
  File "/usr/local/lib/python2.7/dist-packages/django/utils/decorators.py", line 25, in _wrapper
    return bound_func(*args, **kwargs)
  File "/usr/local/lib/python2.7/dist-packages/django/contrib/auth/decorators.py", line 20, in _wrapped_view
    return view_func(request, *args, **kwargs)
  File "/usr/local/lib/python2.7/dist-packages/django/utils/decorators.py", line 21, in bound_func
    return func(self, *args2, **kwargs2)
  File "/home/picasso/git/export/export/nutep/views.py", line 53, in dispatch
    return super(BaseView, self).dispatch(*args, **kwargs)
  File "/usr/local/lib/python2.7/dist-packages/django/views/generic/base.py", line 69, in dispatch
    return handler(request, *args, **kwargs)
  File "/usr/local/lib/python2.7/dist-packages/django/views/generic/base.py", line 123, in get
    context = self.get_context_data(**kwargs)
  File "/home/picasso/git/export/export/nutep/views.py", line 98, in get_context_data
    draft_service = DraftService(WEB_SERVISES['draft'])
  File "/home/picasso/git/export/export/nutep/services.py", line 15, in __init__
    self.set_client(settings)
  File "/home/picasso/git/export/export/nutep/services.py", line 25, in set_client
    self._client = Client(self.url, headers=authenticationHeader, cache=NoCache())
  File "/usr/local/lib/python2.7/dist-packages/suds/client.py", line 112, in __init__
    self.wsdl = reader.open(url)
  File "/usr/local/lib/python2.7/dist-packages/suds/reader.py", line 152, in open
    d = self.fn(url, self.options)
  File "/usr/local/lib/python2.7/dist-packages/suds/wsdl.py", line 136, in __init__
    d = reader.open(url)
  File "/usr/local/lib/python2.7/dist-packages/suds/reader.py", line 79, in open
    d = self.download(url)
  File "/usr/local/lib/python2.7/dist-packages/suds/reader.py", line 95, in download
    fp = self.options.transport.open(Request(url))
  File "/usr/local/lib/python2.7/dist-packages/suds/transport/https.py", line 60, in open
    return  HttpTransport.open(self, request)
  File "/usr/local/lib/python2.7/dist-packages/suds/transport/http.py", line 62, in open
    return self.u2open(u2request)
  File "/usr/local/lib/python2.7/dist-packages/suds/transport/http.py", line 118, in u2open
    return url.open(u2request, timeout=tm)
  File "/usr/lib/python2.7/urllib2.py", line 401, in open
    response = self._open(req, data)
  File "/usr/lib/python2.7/urllib2.py", line 419, in _open
    '_open', req)
  File "/usr/lib/python2.7/urllib2.py", line 379, in _call_chain
    result = func(*args)
  File "/usr/lib/python2.7/urllib2.py", line 1211, in http_open
    return self.do_open(httplib.HTTPConnection, req)
  File "/usr/lib/python2.7/urllib2.py", line 1184, in do_open
    r = h.getresponse(buffering=True)
  File "/usr/lib/python2.7/httplib.py", line 1072, in getresponse
    response.begin()
  File "/usr/lib/python2.7/httplib.py", line 408, in begin
    version, status, reason = self._read_status()
  File "/usr/lib/python2.7/httplib.py", line 366, in _read_status
    line = self.fp.readline()
  File "/usr/lib/python2.7/socket.py", line 447, in readline
    data = self._sock.recv(self._rbufsize)
timeout: timed out
[17/Mar/2017 11:02:43] ERROR [django.request:213] Internal Server Error: /templatedetails/34
Traceback (most recent call last):
  File "/usr/local/lib/python2.7/dist-packages/django/core/handlers/base.py", line 109, in get_response
    response = callback(request, *callback_args, **callback_kwargs)
  File "/usr/local/lib/python2.7/dist-packages/django/views/generic/base.py", line 48, in view
    return self.dispatch(request, *args, **kwargs)
  File "/usr/local/lib/python2.7/dist-packages/django/utils/decorators.py", line 25, in _wrapper
    return bound_func(*args, **kwargs)
  File "/usr/local/lib/python2.7/dist-packages/django/contrib/auth/decorators.py", line 20, in _wrapped_view
    return view_func(request, *args, **kwargs)
  File "/usr/local/lib/python2.7/dist-packages/django/utils/decorators.py", line 21, in bound_func
    return func(self, *args2, **kwargs2)
  File "/home/picasso/git/export/export/nutep/views.py", line 53, in dispatch
    return super(BaseView, self).dispatch(*args, **kwargs)
  File "/usr/local/lib/python2.7/dist-packages/django/views/generic/base.py", line 69, in dispatch
    return handler(request, *args, **kwargs)
  File "/usr/local/lib/python2.7/dist-packages/django/views/generic/base.py", line 123, in get
    context = self.get_context_data(**kwargs)
  File "/home/picasso/git/export/export/nutep/views.py", line 99, in get_context_data
    draft_service.update_status(pk)
  File "/home/picasso/git/export/export/nutep/services.py", line 76, in update_status
    response = self._client.service.GetStatus(pk)
  File "/usr/local/lib/python2.7/dist-packages/suds/client.py", line 542, in __call__
    return client.invoke(args, kwargs)
  File "/usr/local/lib/python2.7/dist-packages/suds/client.py", line 602, in invoke
    result = self.send(soapenv)
  File "/usr/local/lib/python2.7/dist-packages/suds/client.py", line 637, in send
    reply = transport.send(request)
  File "/usr/local/lib/python2.7/dist-packages/suds/transport/https.py", line 64, in send
    return  HttpTransport.send(self, request)
  File "/usr/local/lib/python2.7/dist-packages/suds/transport/http.py", line 77, in send
    fp = self.u2open(u2request)
  File "/usr/local/lib/python2.7/dist-packages/suds/transport/http.py", line 118, in u2open
    return url.open(u2request, timeout=tm)
  File "/usr/lib/python2.7/urllib2.py", line 401, in open
    response = self._open(req, data)
  File "/usr/lib/python2.7/urllib2.py", line 419, in _open
    '_open', req)
  File "/usr/lib/python2.7/urllib2.py", line 379, in _call_chain
    result = func(*args)
  File "/usr/lib/python2.7/urllib2.py", line 1211, in http_open
    return self.do_open(httplib.HTTPConnection, req)
  File "/usr/lib/python2.7/urllib2.py", line 1184, in do_open
    r = h.getresponse(buffering=True)
  File "/usr/lib/python2.7/httplib.py", line 1072, in getresponse
    response.begin()
  File "/usr/lib/python2.7/httplib.py", line 408, in begin
    version, status, reason = self._read_status()
  File "/usr/lib/python2.7/httplib.py", line 366, in _read_status
    line = self.fp.readline()
  File "/usr/lib/python2.7/socket.py", line 447, in readline
    data = self._sock.recv(self._rbufsize)
timeout: timed out
[17/Mar/2017 11:38:39] ERROR [django.request:213] Internal Server Error: /gettemplate/32
Traceback (most recent call last):
  File "/usr/local/lib/python2.7/dist-packages/django/core/handlers/base.py", line 109, in get_response
    response = callback(request, *callback_args, **callback_kwargs)
  File "/usr/local/lib/python2.7/dist-packages/django/contrib/auth/decorators.py", line 20, in _wrapped_view
    return view_func(request, *args, **kwargs)
  File "/home/picasso/git/export/export/nutep/views.py", line 143, in get_template_status
    status = draft_service.update_status(pk)
  File "/home/picasso/git/export/export/nutep/services.py", line 73, in update_status
    template = UploadedTemplate.objects.get(pk=pk)
  File "/usr/local/lib/python2.7/dist-packages/django/db/models/manager.py", line 131, in get
    return self.get_query_set().get(*args, **kwargs)
  File "/usr/local/lib/python2.7/dist-packages/django/db/models/query.py", line 366, in get
    % self.model._meta.object_name)
DoesNotExist: UploadedTemplate matching query does not exist.
[17/Mar/2017 11:38:55] ERROR [django.request:213] Internal Server Error: /gettemplate/34
Traceback (most recent call last):
  File "/usr/local/lib/python2.7/dist-packages/django/core/handlers/base.py", line 109, in get_response
    response = callback(request, *callback_args, **callback_kwargs)
  File "/usr/local/lib/python2.7/dist-packages/django/contrib/auth/decorators.py", line 20, in _wrapped_view
    return view_func(request, *args, **kwargs)
  File "/home/picasso/git/export/export/nutep/views.py", line 144, in get_template_status
    return HttpResponse(json.dumps({'status':status}), content_type="application/json")
  File "/usr/lib/python2.7/json/__init__.py", line 231, in dumps
    return _default_encoder.encode(obj)
  File "/usr/lib/python2.7/json/encoder.py", line 200, in encode
    chunks = self.iterencode(o, _one_shot=True)
  File "/usr/lib/python2.7/json/encoder.py", line 263, in iterencode
    return _iterencode(o, 0)
  File "/usr/lib/python2.7/json/encoder.py", line 177, in default
    raise TypeError(repr(o) + " is not JSON serializable")
TypeError: (Data){
   errors = ""
   voyage = 
      (Voyage){
         name = "YMIRM099S"
         guid = "7f951acc-f5f2-11e6-80d1-00505693104b"
         etd = 2017-02-27
         vessel = 
            (Vessel){
               name = "YM INCREMENT"
               guid = "f031bd22-f5c7-11e6-80d1-00505693104b"
            }
         flag = "DENMARK"
      }
   terminal = 
      (Terminal){
         name = "NUTEP"
         guid = "560e730c-269f-41b9-9c04-988cb38f1467"
      }
   drafts = 
      (Drafts){
         draft[] = 
            (Draft){
               name = "COEU9000396290"
               guid = "314ba3e4-fc64-11e6-80d3-00505693104b"
               containers = 
                  (Containers){
                     container[] = 
                        (Container){
                           name = "CBHU 3600037"
                           SOC = False
                           size = "40"
                           type = "HC"
                           line = 
                              (Line){
                                 name = "COSCO"
                                 guid = "6d9e6058-0ad5-11dd-bbaf-001b789d9c16"
                              }
                           seal = None
                           cargo = "МАСЛО"
                           netto = 0
                           gross = 28000
                           tare = 4000
                           package = None
                           quantity = 0
                        },
                        (Container){
                           name = "FCIU 4819687"
                           SOC = False
                           size = "40"
                           type = "HC"
                           line = 
                              (Line){
                                 name = "COSCO"
                                 guid = "6d9e6058-0ad5-11dd-bbaf-001b789d9c16"
                              }
                           seal = None
                           cargo = None
                           netto = 0
                           gross = 28000
                           tare = 4000
                           package = None
                           quantity = 0
                        },
                        (Container){
                           name = "RFCU 2085091"
                           SOC = False
                           size = "40"
                           type = "HC"
                           line = 
                              (Line){
                                 name = "COSCO"
                                 guid = "6d9e6058-0ad5-11dd-bbaf-001b789d9c16"
                              }
                           seal = None
                           cargo = "МАСЛО"
                           netto = 0
                           gross = 28000
                           tare = 4000
                           package = None
                           quantity = 0
                        },
                  }
               date = 2017-02-25
               shipper = "COSCO NOVO LTD"
               consignee = "COSCO SHIPPING AGENCY (GREECE) S.A. - PIRAEUS"
               voyage = 
                  (Voyage){
                     name = "YMIRM099S"
                     guid = "7f951acc-f5f2-11e6-80d1-00505693104b"
                     etd = 2017-02-27
                     vessel = 
                        (Vessel){
                           name = "YM INCREMENT"
                           guid = "f031bd22-f5c7-11e6-80d1-00505693104b"
                        }
                     flag = "DENMARK"
                  }
               finalDestination = "ANTWERPEN"
               POD = "PIRAEUS"
               POL = "NOVOROSSIYSK"
               finstatus = False
               status = False
               poruchenie = False
               poruchenieNums = None
               notify = "COSCO SHIPPING AGENCY (GREECE) S.A. - PIRAEUS"
               line = 
                  (Line){
                     name = "COSCO"
                     guid = "6d9e6058-0ad5-11dd-bbaf-001b789d9c16"
                  }
               userguid = "947002eb-c3ff-11e1-b440-000c29113788"
               readiness = 
                  (DraftReadiness){
                     row[] = 
                        (ReadinessRow){
                           size = "40"
                           type = "HC"
                           ordered = 3
                           done = 3
                        },
                  }
            },
            (Draft){
               name = "COEU9000396291"
               guid = "50d9e970-04b0-11e7-80d5-00505693104b"
               containers = 
                  (Containers){
                     container[] = 
                        (Container){
                           name = "CBHU 5743947"
                           SOC = False
                           size = "40"
                           type = "HC"
                           line = 
                              (Line){
                                 name = "COSCO"
                                 guid = "6d9e6058-0ad5-11dd-bbaf-001b789d9c16"
                              }
                           seal = None
                           cargo = None
                           netto = 0
                           gross = 28000
                           tare = 4000
                           package = None
                           quantity = 0
                        },
                        (Container){
                           name = "MRKU 7220274"
                           SOC = False
                           size = "40"
                           type = "HC"
                           line = 
                              (Line){
                                 name = "COSCO"
                                 guid = "6d9e6058-0ad5-11dd-bbaf-001b789d9c16"
                              }
                           seal = None
                           cargo = None
                           netto = 0
                           gross = 28000
                           tare = 0
                           package = None
                           quantity = 0
                        },
                  }
               date = 2017-02-25
               shipper = "COSCO NOVO LTD"
               consignee = "COSCO SHIPPING AGENCY (GREECE) S.A. - PIRAEUS"
               voyage = 
                  (Voyage){
                     name = "YMIRM099S"
                     guid = "7f951acc-f5f2-11e6-80d1-00505693104b"
                     etd = 2017-02-27
                     vessel = 
                        (Vessel){
                           name = "YM INCREMENT"
                           guid = "f031bd22-f5c7-11e6-80d1-00505693104b"
                        }
                     flag = "DENMARK"
                  }
               finalDestination = "ANTWERPEN"
               POD = "PIRAEUS"
               POL = "NOVOROSSIYSK"
               finstatus = False
               status = False
               poruchenie = False
               poruchenieNums = None
               notify = "COSCO SHIPPING AGENCY (GREECE) S.A. - PIRAEUS"
               line = 
                  (Line){
                     name = "COSCO"
                     guid = "6d9e6058-0ad5-11dd-bbaf-001b789d9c16"
                  }
               userguid = "947002eb-c3ff-11e1-b440-000c29113788"
               readiness = 
                  (DraftReadiness){
                     row[] = 
                        (ReadinessRow){
                           size = "40"
                           type = "HC"
                           ordered = 2
                           done = 2
                        },
                  }
            },
      }
   contract = 
      (Contract){
         name = "COSCO-10-2012"
         guid = "3639ce20-7782-11e3-9439-000c29c1ffac"
      }
 } is not JSON serializable
[17/Mar/2017 11:43:28] ERROR [django.request:213] Internal Server Error: /gettemplate/34
Traceback (most recent call last):
  File "/usr/local/lib/python2.7/dist-packages/django/core/handlers/base.py", line 127, in get_response
    raise ValueError("The view %s.%s didn't return an HttpResponse object." % (callback.__module__, view_name))
ValueError: The view nutep.views.get_template_status didn't return an HttpResponse object.
[17/Mar/2017 11:44:39] ERROR [django.request:213] Internal Server Error: /gettemplate/34
Traceback (most recent call last):
  File "/usr/local/lib/python2.7/dist-packages/django/core/handlers/base.py", line 127, in get_response
    raise ValueError("The view %s.%s didn't return an HttpResponse object." % (callback.__module__, view_name))
ValueError: The view nutep.views.get_template_status didn't return an HttpResponse object.
[17/Mar/2017 11:44:40] ERROR [django.request:213] Internal Server Error: /gettemplate/34
Traceback (most recent call last):
  File "/usr/local/lib/python2.7/dist-packages/django/core/handlers/base.py", line 127, in get_response
    raise ValueError("The view %s.%s didn't return an HttpResponse object." % (callback.__module__, view_name))
ValueError: The view nutep.views.get_template_status didn't return an HttpResponse object.
[17/Mar/2017 11:44:41] ERROR [django.request:213] Internal Server Error: /gettemplate/34
Traceback (most recent call last):
  File "/usr/local/lib/python2.7/dist-packages/django/core/handlers/base.py", line 127, in get_response
    raise ValueError("The view %s.%s didn't return an HttpResponse object." % (callback.__module__, view_name))
ValueError: The view nutep.views.get_template_status didn't return an HttpResponse object.
[17/Mar/2017 11:44:41] ERROR [django.request:213] Internal Server Error: /gettemplate/34
Traceback (most recent call last):
  File "/usr/local/lib/python2.7/dist-packages/django/core/handlers/base.py", line 127, in get_response
    raise ValueError("The view %s.%s didn't return an HttpResponse object." % (callback.__module__, view_name))
ValueError: The view nutep.views.get_template_status didn't return an HttpResponse object.
[17/Mar/2017 11:44:42] ERROR [django.request:213] Internal Server Error: /gettemplate/34
Traceback (most recent call last):
  File "/usr/local/lib/python2.7/dist-packages/django/core/handlers/base.py", line 127, in get_response
    raise ValueError("The view %s.%s didn't return an HttpResponse object." % (callback.__module__, view_name))
ValueError: The view nutep.views.get_template_status didn't return an HttpResponse object.
[17/Mar/2017 11:44:42] ERROR [django.request:213] Internal Server Error: /gettemplate/34
Traceback (most recent call last):
  File "/usr/local/lib/python2.7/dist-packages/django/core/handlers/base.py", line 127, in get_response
    raise ValueError("The view %s.%s didn't return an HttpResponse object." % (callback.__module__, view_name))
ValueError: The view nutep.views.get_template_status didn't return an HttpResponse object.
[17/Mar/2017 11:44:42] ERROR [django.request:213] Internal Server Error: /gettemplate/34
Traceback (most recent call last):
  File "/usr/local/lib/python2.7/dist-packages/django/core/handlers/base.py", line 127, in get_response
    raise ValueError("The view %s.%s didn't return an HttpResponse object." % (callback.__module__, view_name))
ValueError: The view nutep.views.get_template_status didn't return an HttpResponse object.
[17/Mar/2017 13:36:29] ERROR [django.request:213] Internal Server Error: /gettemplate/34
Traceback (most recent call last):
  File "/usr/local/lib/python2.7/dist-packages/django/core/handlers/base.py", line 109, in get_response
    response = callback(request, *callback_args, **callback_kwargs)
  File "/usr/local/lib/python2.7/dist-packages/django/views/decorators/http.py", line 41, in inner
    return func(request, *args, **kwargs)
  File "/usr/local/lib/python2.7/dist-packages/django/contrib/auth/decorators.py", line 20, in _wrapped_view
    return view_func(request, *args, **kwargs)
  File "/home/picasso/git/export/export/nutep/views.py", line 145, in get_template_status
    draft_service = DraftService(WEB_SERVISES['draft'])
  File "/home/picasso/git/export/export/nutep/services.py", line 13, in __init__
    self.set_client(settings)
  File "/home/picasso/git/export/export/nutep/services.py", line 23, in set_client
    self._client = Client(self.url, headers=authenticationHeader, cache=NoCache(), timeout=500)
  File "/usr/local/lib/python2.7/dist-packages/suds/client.py", line 112, in __init__
    self.wsdl = reader.open(url)
  File "/usr/local/lib/python2.7/dist-packages/suds/reader.py", line 152, in open
    d = self.fn(url, self.options)
  File "/usr/local/lib/python2.7/dist-packages/suds/wsdl.py", line 136, in __init__
    d = reader.open(url)
  File "/usr/local/lib/python2.7/dist-packages/suds/reader.py", line 79, in open
    d = self.download(url)
  File "/usr/local/lib/python2.7/dist-packages/suds/reader.py", line 95, in download
    fp = self.options.transport.open(Request(url))
  File "/usr/local/lib/python2.7/dist-packages/suds/transport/https.py", line 60, in open
    return  HttpTransport.open(self, request)
  File "/usr/local/lib/python2.7/dist-packages/suds/transport/http.py", line 64, in open
    raise TransportError(str(e), e.code, e.fp)
TransportError: HTTP Error 502: Bad gateway
[17/Mar/2017 13:52:39] ERROR [django.request:213] Internal Server Error: /gettemplate/34
Traceback (most recent call last):
  File "/usr/local/lib/python2.7/dist-packages/django/core/handlers/base.py", line 109, in get_response
    response = callback(request, *callback_args, **callback_kwargs)
  File "/usr/local/lib/python2.7/dist-packages/django/views/decorators/http.py", line 41, in inner
    return func(request, *args, **kwargs)
  File "/usr/local/lib/python2.7/dist-packages/django/contrib/auth/decorators.py", line 20, in _wrapped_view
    return view_func(request, *args, **kwargs)
  File "/home/picasso/git/export/export/nutep/views.py", line 145, in get_template_status
    draft_service = DraftService(WEB_SERVISES['draft'])
  File "/home/picasso/git/export/export/nutep/services.py", line 13, in __init__
    self.set_client(settings)
  File "/home/picasso/git/export/export/nutep/services.py", line 23, in set_client
    self._client = Client(self.url, headers=authenticationHeader, cache=NoCache(), timeout=500)
  File "/usr/local/lib/python2.7/dist-packages/suds/client.py", line 112, in __init__
    self.wsdl = reader.open(url)
  File "/usr/local/lib/python2.7/dist-packages/suds/reader.py", line 152, in open
    d = self.fn(url, self.options)
  File "/usr/local/lib/python2.7/dist-packages/suds/wsdl.py", line 136, in __init__
    d = reader.open(url)
  File "/usr/local/lib/python2.7/dist-packages/suds/reader.py", line 79, in open
    d = self.download(url)
  File "/usr/local/lib/python2.7/dist-packages/suds/reader.py", line 95, in download
    fp = self.options.transport.open(Request(url))
  File "/usr/local/lib/python2.7/dist-packages/suds/transport/https.py", line 60, in open
    return  HttpTransport.open(self, request)
  File "/usr/local/lib/python2.7/dist-packages/suds/transport/http.py", line 64, in open
    raise TransportError(str(e), e.code, e.fp)
TransportError: HTTP Error 502: Bad gateway
[17/Mar/2017 14:00:43] ERROR [django.request:213] Internal Server Error: /gettemplate/34
Traceback (most recent call last):
  File "/usr/local/lib/python2.7/dist-packages/django/core/handlers/base.py", line 109, in get_response
    response = callback(request, *callback_args, **callback_kwargs)
  File "/usr/local/lib/python2.7/dist-packages/django/views/decorators/http.py", line 41, in inner
    return func(request, *args, **kwargs)
  File "/usr/local/lib/python2.7/dist-packages/django/contrib/auth/decorators.py", line 20, in _wrapped_view
    return view_func(request, *args, **kwargs)
  File "/home/picasso/git/export/export/nutep/views.py", line 145, in get_template_status
    draft_service = DraftService(WEB_SERVISES['draft'])
  File "/home/picasso/git/export/export/nutep/services.py", line 13, in __init__
    self.set_client(settings)
  File "/home/picasso/git/export/export/nutep/services.py", line 23, in set_client
    self._client = Client(self.url, headers=authenticationHeader, cache=NoCache(), timeout=500)
  File "/usr/local/lib/python2.7/dist-packages/suds/client.py", line 112, in __init__
    self.wsdl = reader.open(url)
  File "/usr/local/lib/python2.7/dist-packages/suds/reader.py", line 152, in open
    d = self.fn(url, self.options)
  File "/usr/local/lib/python2.7/dist-packages/suds/wsdl.py", line 136, in __init__
    d = reader.open(url)
  File "/usr/local/lib/python2.7/dist-packages/suds/reader.py", line 79, in open
    d = self.download(url)
  File "/usr/local/lib/python2.7/dist-packages/suds/reader.py", line 95, in download
    fp = self.options.transport.open(Request(url))
  File "/usr/local/lib/python2.7/dist-packages/suds/transport/https.py", line 60, in open
    return  HttpTransport.open(self, request)
  File "/usr/local/lib/python2.7/dist-packages/suds/transport/http.py", line 64, in open
    raise TransportError(str(e), e.code, e.fp)
TransportError: HTTP Error 502: Bad gateway
[17/Mar/2017 14:04:10] ERROR [django.request:213] Internal Server Error: /gettemplate/34
Traceback (most recent call last):
  File "/usr/local/lib/python2.7/dist-packages/django/core/handlers/base.py", line 109, in get_response
    response = callback(request, *callback_args, **callback_kwargs)
  File "/usr/local/lib/python2.7/dist-packages/django/views/decorators/http.py", line 41, in inner
    return func(request, *args, **kwargs)
  File "/usr/local/lib/python2.7/dist-packages/django/contrib/auth/decorators.py", line 20, in _wrapped_view
    return view_func(request, *args, **kwargs)
  File "/home/picasso/git/export/export/nutep/views.py", line 145, in get_template_status
    draft_service = DraftService(WEB_SERVISES['draft'])
  File "/home/picasso/git/export/export/nutep/services.py", line 13, in __init__
    self.set_client(settings)
  File "/home/picasso/git/export/export/nutep/services.py", line 23, in set_client
    self._client = Client(self.url, headers=authenticationHeader, cache=NoCache(), timeout=500)
  File "/usr/local/lib/python2.7/dist-packages/suds/client.py", line 112, in __init__
    self.wsdl = reader.open(url)
  File "/usr/local/lib/python2.7/dist-packages/suds/reader.py", line 152, in open
    d = self.fn(url, self.options)
  File "/usr/local/lib/python2.7/dist-packages/suds/wsdl.py", line 136, in __init__
    d = reader.open(url)
  File "/usr/local/lib/python2.7/dist-packages/suds/reader.py", line 79, in open
    d = self.download(url)
  File "/usr/local/lib/python2.7/dist-packages/suds/reader.py", line 95, in download
    fp = self.options.transport.open(Request(url))
  File "/usr/local/lib/python2.7/dist-packages/suds/transport/https.py", line 60, in open
    return  HttpTransport.open(self, request)
  File "/usr/local/lib/python2.7/dist-packages/suds/transport/http.py", line 64, in open
    raise TransportError(str(e), e.code, e.fp)
TransportError: HTTP Error 502: Bad gateway
[17/Mar/2017 14:04:45] ERROR [django.request:213] Internal Server Error: /gettemplate/34
Traceback (most recent call last):
  File "/usr/local/lib/python2.7/dist-packages/django/core/handlers/base.py", line 109, in get_response
    response = callback(request, *callback_args, **callback_kwargs)
  File "/usr/local/lib/python2.7/dist-packages/django/views/decorators/http.py", line 41, in inner
    return func(request, *args, **kwargs)
  File "/usr/local/lib/python2.7/dist-packages/django/contrib/auth/decorators.py", line 20, in _wrapped_view
    return view_func(request, *args, **kwargs)
  File "/home/picasso/git/export/export/nutep/views.py", line 145, in get_template_status
    draft_service = DraftService(WEB_SERVISES['draft'])
  File "/home/picasso/git/export/export/nutep/services.py", line 13, in __init__
    self.set_client(settings)
  File "/home/picasso/git/export/export/nutep/services.py", line 23, in set_client
    self._client = Client(self.url, headers=authenticationHeader, cache=NoCache(), timeout=500)
  File "/usr/local/lib/python2.7/dist-packages/suds/client.py", line 112, in __init__
    self.wsdl = reader.open(url)
  File "/usr/local/lib/python2.7/dist-packages/suds/reader.py", line 152, in open
    d = self.fn(url, self.options)
  File "/usr/local/lib/python2.7/dist-packages/suds/wsdl.py", line 136, in __init__
    d = reader.open(url)
  File "/usr/local/lib/python2.7/dist-packages/suds/reader.py", line 79, in open
    d = self.download(url)
  File "/usr/local/lib/python2.7/dist-packages/suds/reader.py", line 95, in download
    fp = self.options.transport.open(Request(url))
  File "/usr/local/lib/python2.7/dist-packages/suds/transport/https.py", line 60, in open
    return  HttpTransport.open(self, request)
  File "/usr/local/lib/python2.7/dist-packages/suds/transport/http.py", line 64, in open
    raise TransportError(str(e), e.code, e.fp)
TransportError: HTTP Error 502: Bad gateway
[21/Mar/2017 12:47:19] ERROR [django.request:213] Internal Server Error: /templatedetails/34
Traceback (most recent call last):
  File "/usr/local/lib/python2.7/dist-packages/django/core/handlers/base.py", line 109, in get_response
    response = callback(request, *callback_args, **callback_kwargs)
  File "/usr/local/lib/python2.7/dist-packages/django/views/generic/base.py", line 48, in view
    return self.dispatch(request, *args, **kwargs)
  File "/usr/local/lib/python2.7/dist-packages/django/utils/decorators.py", line 25, in _wrapper
    return bound_func(*args, **kwargs)
  File "/usr/local/lib/python2.7/dist-packages/django/contrib/auth/decorators.py", line 20, in _wrapped_view
    return view_func(request, *args, **kwargs)
  File "/usr/local/lib/python2.7/dist-packages/django/utils/decorators.py", line 21, in bound_func
    return func(self, *args2, **kwargs2)
  File "/home/picasso/git/export/export/nutep/views.py", line 58, in dispatch
    return super(BaseView, self).dispatch(*args, **kwargs)
  File "/usr/local/lib/python2.7/dist-packages/django/views/generic/base.py", line 69, in dispatch
    return handler(request, *args, **kwargs)
  File "/usr/local/lib/python2.7/dist-packages/django/views/generic/base.py", line 123, in get
    context = self.get_context_data(**kwargs)
  File "/home/picasso/git/export/export/nutep/views.py", line 104, in get_context_data
    context = super(TemplateDetailView, self).get_context_data(**kwargs)
  File "/home/picasso/git/export/export/nutep/views.py", line 61, in get_context_data
    vessels = Vessel.objects.filter(history__user__lines__in=self.request.user.lines.all()).distinct()
  File "/usr/local/lib/python2.7/dist-packages/django/utils/functional.py", line 185, in inner
    return func(self._wrapped, *args)
AttributeError: 'User' object has no attribute 'lines'
[21/Mar/2017 12:47:56] ERROR [django.request:213] Internal Server Error: /templatedetails/34
Traceback (most recent call last):
  File "/usr/local/lib/python2.7/dist-packages/django/core/handlers/base.py", line 109, in get_response
    response = callback(request, *callback_args, **callback_kwargs)
  File "/usr/local/lib/python2.7/dist-packages/django/views/generic/base.py", line 48, in view
    return self.dispatch(request, *args, **kwargs)
  File "/usr/local/lib/python2.7/dist-packages/django/utils/decorators.py", line 25, in _wrapper
    return bound_func(*args, **kwargs)
  File "/usr/local/lib/python2.7/dist-packages/django/contrib/auth/decorators.py", line 20, in _wrapped_view
    return view_func(request, *args, **kwargs)
  File "/usr/local/lib/python2.7/dist-packages/django/utils/decorators.py", line 21, in bound_func
    return func(self, *args2, **kwargs2)
  File "/home/picasso/git/export/export/nutep/views.py", line 58, in dispatch
    return super(BaseView, self).dispatch(*args, **kwargs)
  File "/usr/local/lib/python2.7/dist-packages/django/views/generic/base.py", line 69, in dispatch
    return handler(request, *args, **kwargs)
  File "/usr/local/lib/python2.7/dist-packages/django/views/generic/base.py", line 123, in get
    context = self.get_context_data(**kwargs)
  File "/home/picasso/git/export/export/nutep/views.py", line 104, in get_context_data
    context = super(TemplateDetailView, self).get_context_data(**kwargs)
  File "/home/picasso/git/export/export/nutep/views.py", line 61, in get_context_data
    vessels = Vessel.objects.filter(history__user__profile__lines__in=self.request.user.profile.lines.all()).distinct()
AttributeError: 'RelatedManager' object has no attribute 'lines'
