[05/Mar/2017 23:47:11] ERROR [django.request:213] Internal Server Error: /upload/
Traceback (most recent call last):
  File "/usr/local/lib/python2.7/dist-packages/django/core/handlers/base.py", line 109, in get_response
    response = callback(request, *callback_args, **callback_kwargs)
  File "/usr/local/lib/python2.7/dist-packages/django/contrib/auth/decorators.py", line 20, in _wrapped_view
    return view_func(request, *args, **kwargs)
  File "/home/picasso/git/export/export/nutep/views.py", line 213, in upload_file
    draft_service.load_draft(template, request.user)
  File "/home/picasso/git/export/export/nutep/services.py", line 67, in load_draft
    response = self._client.service.LoadDraft(xml_template)
  File "/usr/local/lib/python2.7/dist-packages/suds/client.py", line 542, in __call__
    return client.invoke(args, kwargs)
  File "/usr/local/lib/python2.7/dist-packages/suds/client.py", line 602, in invoke
    result = self.send(soapenv)
  File "/usr/local/lib/python2.7/dist-packages/suds/client.py", line 637, in send
    reply = transport.send(request)
  File "/usr/local/lib/python2.7/dist-packages/suds/transport/https.py", line 64, in send
    return  HttpTransport.send(self, request)
  File "/usr/local/lib/python2.7/dist-packages/suds/transport/http.py", line 77, in send
    fp = self.u2open(u2request)
  File "/usr/local/lib/python2.7/dist-packages/suds/transport/http.py", line 118, in u2open
    return url.open(u2request, timeout=tm)
  File "/usr/lib/python2.7/urllib2.py", line 401, in open
    response = self._open(req, data)
  File "/usr/lib/python2.7/urllib2.py", line 419, in _open
    '_open', req)
  File "/usr/lib/python2.7/urllib2.py", line 379, in _call_chain
    result = func(*args)
  File "/usr/lib/python2.7/urllib2.py", line 1211, in http_open
    return self.do_open(httplib.HTTPConnection, req)
  File "/usr/lib/python2.7/urllib2.py", line 1184, in do_open
    r = h.getresponse(buffering=True)
  File "/usr/lib/python2.7/httplib.py", line 1072, in getresponse
    response.begin()
  File "/usr/lib/python2.7/httplib.py", line 408, in begin
    version, status, reason = self._read_status()
  File "/usr/lib/python2.7/httplib.py", line 366, in _read_status
    line = self.fp.readline()
  File "/usr/lib/python2.7/socket.py", line 447, in readline
    data = self._sock.recv(self._rbufsize)
timeout: timed out
[05/Mar/2017 23:52:08] ERROR [django.request:213] Internal Server Error: /upload/
Traceback (most recent call last):
  File "/usr/local/lib/python2.7/dist-packages/django/core/handlers/base.py", line 109, in get_response
    response = callback(request, *callback_args, **callback_kwargs)
  File "/usr/local/lib/python2.7/dist-packages/django/contrib/auth/decorators.py", line 20, in _wrapped_view
    return view_func(request, *args, **kwargs)
  File "/home/picasso/git/export/export/nutep/views.py", line 213, in upload_file
    draft_service.load_draft(template, request.user)
  File "/home/picasso/git/export/export/nutep/services.py", line 67, in load_draft
    response = self._client.service.LoadDraft(xml_template)
  File "/usr/local/lib/python2.7/dist-packages/suds/client.py", line 542, in __call__
    return client.invoke(args, kwargs)
  File "/usr/local/lib/python2.7/dist-packages/suds/client.py", line 602, in invoke
    result = self.send(soapenv)
  File "/usr/local/lib/python2.7/dist-packages/suds/client.py", line 637, in send
    reply = transport.send(request)
  File "/usr/local/lib/python2.7/dist-packages/suds/transport/https.py", line 64, in send
    return  HttpTransport.send(self, request)
  File "/usr/local/lib/python2.7/dist-packages/suds/transport/http.py", line 77, in send
    fp = self.u2open(u2request)
  File "/usr/local/lib/python2.7/dist-packages/suds/transport/http.py", line 118, in u2open
    return url.open(u2request, timeout=tm)
  File "/usr/lib/python2.7/urllib2.py", line 401, in open
    response = self._open(req, data)
  File "/usr/lib/python2.7/urllib2.py", line 419, in _open
    '_open', req)
  File "/usr/lib/python2.7/urllib2.py", line 379, in _call_chain
    result = func(*args)
  File "/usr/lib/python2.7/urllib2.py", line 1211, in http_open
    return self.do_open(httplib.HTTPConnection, req)
  File "/usr/lib/python2.7/urllib2.py", line 1184, in do_open
    r = h.getresponse(buffering=True)
  File "/usr/lib/python2.7/httplib.py", line 1072, in getresponse
    response.begin()
  File "/usr/lib/python2.7/httplib.py", line 408, in begin
    version, status, reason = self._read_status()
  File "/usr/lib/python2.7/httplib.py", line 366, in _read_status
    line = self.fp.readline()
  File "/usr/lib/python2.7/socket.py", line 447, in readline
    data = self._sock.recv(self._rbufsize)
timeout: timed out
[06/Mar/2017 00:00:43] ERROR [django.request:213] Internal Server Error: /upload/
Traceback (most recent call last):
  File "/usr/local/lib/python2.7/dist-packages/django/core/handlers/base.py", line 109, in get_response
    response = callback(request, *callback_args, **callback_kwargs)
  File "/usr/local/lib/python2.7/dist-packages/django/contrib/auth/decorators.py", line 20, in _wrapped_view
    return view_func(request, *args, **kwargs)
  File "/home/picasso/git/export/export/nutep/views.py", line 213, in upload_file
    draft_service.load_draft(template, request.user)
  File "/home/picasso/git/export/export/nutep/services.py", line 67, in load_draft
    response = self._client.service.LoadDraft(xml_template)
  File "/usr/local/lib/python2.7/dist-packages/suds/client.py", line 542, in __call__
    return client.invoke(args, kwargs)
  File "/usr/local/lib/python2.7/dist-packages/suds/client.py", line 602, in invoke
    result = self.send(soapenv)
  File "/usr/local/lib/python2.7/dist-packages/suds/client.py", line 637, in send
    reply = transport.send(request)
  File "/usr/local/lib/python2.7/dist-packages/suds/transport/https.py", line 64, in send
    return  HttpTransport.send(self, request)
  File "/usr/local/lib/python2.7/dist-packages/suds/transport/http.py", line 77, in send
    fp = self.u2open(u2request)
  File "/usr/local/lib/python2.7/dist-packages/suds/transport/http.py", line 118, in u2open
    return url.open(u2request, timeout=tm)
  File "/usr/lib/python2.7/urllib2.py", line 401, in open
    response = self._open(req, data)
  File "/usr/lib/python2.7/urllib2.py", line 419, in _open
    '_open', req)
  File "/usr/lib/python2.7/urllib2.py", line 379, in _call_chain
    result = func(*args)
  File "/usr/lib/python2.7/urllib2.py", line 1211, in http_open
    return self.do_open(httplib.HTTPConnection, req)
  File "/usr/lib/python2.7/urllib2.py", line 1184, in do_open
    r = h.getresponse(buffering=True)
  File "/usr/lib/python2.7/httplib.py", line 1072, in getresponse
    response.begin()
  File "/usr/lib/python2.7/httplib.py", line 408, in begin
    version, status, reason = self._read_status()
  File "/usr/lib/python2.7/httplib.py", line 366, in _read_status
    line = self.fp.readline()
  File "/usr/lib/python2.7/socket.py", line 447, in readline
    data = self._sock.recv(self._rbufsize)
timeout: timed out
[06/Mar/2017 00:27:19] ERROR [django.request:213] Internal Server Error: /upload/
Traceback (most recent call last):
  File "/usr/local/lib/python2.7/dist-packages/django/core/handlers/base.py", line 109, in get_response
    response = callback(request, *callback_args, **callback_kwargs)
  File "/usr/local/lib/python2.7/dist-packages/django/contrib/auth/decorators.py", line 20, in _wrapped_view
    return view_func(request, *args, **kwargs)
  File "/home/picasso/git/export/export/nutep/views.py", line 213, in upload_file
    draft_service.load_draft(template, request.user)
  File "/home/picasso/git/export/export/nutep/services.py", line 67, in load_draft
    response = self._client.service.LoadDraft(xml_template)
  File "/usr/local/lib/python2.7/dist-packages/suds/client.py", line 542, in __call__
    return client.invoke(args, kwargs)
  File "/usr/local/lib/python2.7/dist-packages/suds/client.py", line 602, in invoke
    result = self.send(soapenv)
  File "/usr/local/lib/python2.7/dist-packages/suds/client.py", line 637, in send
    reply = transport.send(request)
  File "/usr/local/lib/python2.7/dist-packages/suds/transport/https.py", line 64, in send
    return  HttpTransport.send(self, request)
  File "/usr/local/lib/python2.7/dist-packages/suds/transport/http.py", line 77, in send
    fp = self.u2open(u2request)
  File "/usr/local/lib/python2.7/dist-packages/suds/transport/http.py", line 118, in u2open
    return url.open(u2request, timeout=tm)
  File "/usr/lib/python2.7/urllib2.py", line 401, in open
    response = self._open(req, data)
  File "/usr/lib/python2.7/urllib2.py", line 419, in _open
    '_open', req)
  File "/usr/lib/python2.7/urllib2.py", line 379, in _call_chain
    result = func(*args)
  File "/usr/lib/python2.7/urllib2.py", line 1211, in http_open
    return self.do_open(httplib.HTTPConnection, req)
  File "/usr/lib/python2.7/urllib2.py", line 1184, in do_open
    r = h.getresponse(buffering=True)
  File "/usr/lib/python2.7/httplib.py", line 1072, in getresponse
    response.begin()
  File "/usr/lib/python2.7/httplib.py", line 408, in begin
    version, status, reason = self._read_status()
  File "/usr/lib/python2.7/httplib.py", line 366, in _read_status
    line = self.fp.readline()
  File "/usr/lib/python2.7/socket.py", line 447, in readline
    data = self._sock.recv(self._rbufsize)
timeout: timed out
[06/Mar/2017 00:40:54] ERROR [django.request:213] Internal Server Error: /upload/
Traceback (most recent call last):
  File "/usr/local/lib/python2.7/dist-packages/django/core/handlers/base.py", line 109, in get_response
    response = callback(request, *callback_args, **callback_kwargs)
  File "/usr/local/lib/python2.7/dist-packages/django/contrib/auth/decorators.py", line 20, in _wrapped_view
    return view_func(request, *args, **kwargs)
  File "/home/picasso/git/export/export/nutep/views.py", line 213, in upload_file
    draft_service.load_draft(template, request.user)
  File "/home/picasso/git/export/export/nutep/services.py", line 67, in load_draft
    response = self._client.service.LoadDraft(xml_template)
  File "/usr/local/lib/python2.7/dist-packages/suds/client.py", line 542, in __call__
    return client.invoke(args, kwargs)
  File "/usr/local/lib/python2.7/dist-packages/suds/client.py", line 602, in invoke
    result = self.send(soapenv)
  File "/usr/local/lib/python2.7/dist-packages/suds/client.py", line 649, in send
    result = self.failed(binding, e)
  File "/usr/local/lib/python2.7/dist-packages/suds/client.py", line 702, in failed
    r, p = binding.get_fault(reply)
  File "/usr/local/lib/python2.7/dist-packages/suds/bindings/binding.py", line 265, in get_fault
    raise WebFault(p, faultroot)
WebFault: Server raised fault: '\u041d\u0435\u0438\u0437\u0432\u0435\u0441\u0442\u043d\u0430\u044f \u043e\u0448\u0438\u0431\u043a\u0430. {Web\u0421\u0435\u0440\u0432\u0438\u0441.\u041e\u0431\u0440\u0430\u0431\u043e\u0442\u043a\u0430\u0417\u0430\u0433\u0440\u0443\u0437\u043a\u0438\u0414\u0440\u0430\u0444\u0442\u043e\u0432.\u041c\u043e\u0434\u0443\u043b\u044c(21)}: \u041e\u0448\u0438\u0431\u043a\u0430 \u043f\u0440\u0438 \u0432\u044b\u0437\u043e\u0432\u0435 \u043c\u0435\u0442\u043e\u0434\u0430 \u043a\u043e\u043d\u0442\u0435\u043a\u0441\u0442\u0430 (\u041f\u043e\u043b\u0443\u0447\u0438\u0442\u044cCOM\u041e\u0431\u044a\u0435\u043a\u0442)
\u043f\u043e \u043f\u0440\u0438\u0447\u0438\u043d\u0435:
{Web\u0421\u0435\u0440\u0432\u0438\u0441.\u041e\u0431\u0440\u0430\u0431\u043e\u0442\u043a\u0430\u0417\u0430\u0433\u0440\u0443\u0437\u043a\u0438\u0414\u0440\u0430\u0444\u0442\u043e\u0432.\u041c\u043e\u0434\u0443\u043b\u044c(21)}: \u041e\u0448\u0438\u0431\u043a\u0430 \u043f\u0440\u0438 \u0432\u044b\u0437\u043e\u0432\u0435 \u043c\u0435\u0442\u043e\u0434\u0430 \u043a\u043e\u043d\u0442\u0435\u043a\u0441\u0442\u0430 (\u041f\u043e\u043b\u0443\u0447\u0438\u0442\u044cCOM\u041e\u0431\u044a\u0435\u043a\u0442)
\u043f\u043e \u043f\u0440\u0438\u0447\u0438\u043d\u0435:
\u041e\u0448\u0438\u0431\u043a\u0430 \u043f\u043e\u043b\u0443\u0447\u0435\u043d\u0438\u044f \u043e\u0431\u044a\u0435\u043a\u0442\u0430 COM: -2147024891(0x80070005): \u041e\u0442\u043a\u0430\u0437\u0430\u043d\u043e \u0432 \u0434\u043e\u0441\u0442\u0443\u043f\u0435. '
[06/Mar/2017 00:43:13] ERROR [django.request:213] Internal Server Error: /upload/
Traceback (most recent call last):
  File "/usr/local/lib/python2.7/dist-packages/django/core/handlers/base.py", line 109, in get_response
    response = callback(request, *callback_args, **callback_kwargs)
  File "/usr/local/lib/python2.7/dist-packages/django/contrib/auth/decorators.py", line 20, in _wrapped_view
    return view_func(request, *args, **kwargs)
  File "/home/picasso/git/export/export/nutep/views.py", line 213, in upload_file
    draft_service.load_draft(template, request.user)
  File "/home/picasso/git/export/export/nutep/services.py", line 67, in load_draft
    response = self._client.service.LoadDraft(xml_template)
  File "/usr/local/lib/python2.7/dist-packages/suds/client.py", line 542, in __call__
    return client.invoke(args, kwargs)
  File "/usr/local/lib/python2.7/dist-packages/suds/client.py", line 602, in invoke
    result = self.send(soapenv)
  File "/usr/local/lib/python2.7/dist-packages/suds/client.py", line 649, in send
    result = self.failed(binding, e)
  File "/usr/local/lib/python2.7/dist-packages/suds/client.py", line 702, in failed
    r, p = binding.get_fault(reply)
  File "/usr/local/lib/python2.7/dist-packages/suds/bindings/binding.py", line 265, in get_fault
    raise WebFault(p, faultroot)
WebFault: Server raised fault: '\u041d\u0435\u0438\u0437\u0432\u0435\u0441\u0442\u043d\u0430\u044f \u043e\u0448\u0438\u0431\u043a\u0430. {Web\u0421\u0435\u0440\u0432\u0438\u0441.\u041e\u0431\u0440\u0430\u0431\u043e\u0442\u043a\u0430\u0417\u0430\u0433\u0440\u0443\u0437\u043a\u0438\u0414\u0440\u0430\u0444\u0442\u043e\u0432.\u041c\u043e\u0434\u0443\u043b\u044c(21)}: \u041e\u0448\u0438\u0431\u043a\u0430 \u043f\u0440\u0438 \u0432\u044b\u0437\u043e\u0432\u0435 \u043c\u0435\u0442\u043e\u0434\u0430 \u043a\u043e\u043d\u0442\u0435\u043a\u0441\u0442\u0430 (\u041f\u043e\u043b\u0443\u0447\u0438\u0442\u044cCOM\u041e\u0431\u044a\u0435\u043a\u0442)
\u043f\u043e \u043f\u0440\u0438\u0447\u0438\u043d\u0435:
{Web\u0421\u0435\u0440\u0432\u0438\u0441.\u041e\u0431\u0440\u0430\u0431\u043e\u0442\u043a\u0430\u0417\u0430\u0433\u0440\u0443\u0437\u043a\u0438\u0414\u0440\u0430\u0444\u0442\u043e\u0432.\u041c\u043e\u0434\u0443\u043b\u044c(21)}: \u041e\u0448\u0438\u0431\u043a\u0430 \u043f\u0440\u0438 \u0432\u044b\u0437\u043e\u0432\u0435 \u043c\u0435\u0442\u043e\u0434\u0430 \u043a\u043e\u043d\u0442\u0435\u043a\u0441\u0442\u0430 (\u041f\u043e\u043b\u0443\u0447\u0438\u0442\u044cCOM\u041e\u0431\u044a\u0435\u043a\u0442)
\u043f\u043e \u043f\u0440\u0438\u0447\u0438\u043d\u0435:
\u041e\u0448\u0438\u0431\u043a\u0430 \u043f\u043e\u043b\u0443\u0447\u0435\u043d\u0438\u044f \u043e\u0431\u044a\u0435\u043a\u0442\u0430 COM: -2147024891(0x80070005): \u041e\u0442\u043a\u0430\u0437\u0430\u043d\u043e \u0432 \u0434\u043e\u0441\u0442\u0443\u043f\u0435. '
[06/Mar/2017 00:48:53] ERROR [django.request:213] Internal Server Error: /upload/
Traceback (most recent call last):
  File "/usr/local/lib/python2.7/dist-packages/django/core/handlers/base.py", line 109, in get_response
    response = callback(request, *callback_args, **callback_kwargs)
  File "/usr/local/lib/python2.7/dist-packages/django/contrib/auth/decorators.py", line 20, in _wrapped_view
    return view_func(request, *args, **kwargs)
  File "/home/picasso/git/export/export/nutep/views.py", line 213, in upload_file
    draft_service.load_draft(template, request.user)
  File "/home/picasso/git/export/export/nutep/services.py", line 67, in load_draft
    response = self._client.service.LoadDraft(xml_template)
  File "/usr/local/lib/python2.7/dist-packages/suds/client.py", line 542, in __call__
    return client.invoke(args, kwargs)
  File "/usr/local/lib/python2.7/dist-packages/suds/client.py", line 602, in invoke
    result = self.send(soapenv)
  File "/usr/local/lib/python2.7/dist-packages/suds/client.py", line 649, in send
    result = self.failed(binding, e)
  File "/usr/local/lib/python2.7/dist-packages/suds/client.py", line 702, in failed
    r, p = binding.get_fault(reply)
  File "/usr/local/lib/python2.7/dist-packages/suds/bindings/binding.py", line 265, in get_fault
    raise WebFault(p, faultroot)
WebFault: Server raised fault: '\u041d\u0435\u0438\u0437\u0432\u0435\u0441\u0442\u043d\u0430\u044f \u043e\u0448\u0438\u0431\u043a\u0430. \u041e\u0448\u0438\u0431\u043a\u0430 \u0438\u043d\u0438\u0446\u0438\u0430\u043b\u0438\u0437\u0430\u0446\u0438\u0438 \u043c\u043e\u0434\u0443\u043b\u044f: \u0421\u043f\u0440\u0430\u0432\u043e\u0447\u043d\u0438\u043a.\u0414\u0440\u0430\u0444\u0442\u043e\u0432\u044b\u0439\u041a\u043e\u043d\u043e\u0441\u0430\u043c\u0435\u043d\u0442.\u041c\u043e\u0434\u0443\u043b\u044c\u041e\u0431\u044a\u0435\u043a\u0442\u0430
\u043f\u043e \u043f\u0440\u0438\u0447\u0438\u043d\u0435:
\u041e\u0448\u0438\u0431\u043a\u0430 \u0438\u043d\u0438\u0446\u0438\u0430\u043b\u0438\u0437\u0430\u0446\u0438\u0438 \u043c\u043e\u0434\u0443\u043b\u044f: \u0421\u043f\u0440\u0430\u0432\u043e\u0447\u043d\u0438\u043a.\u0414\u0440\u0430\u0444\u0442\u043e\u0432\u044b\u0439\u041a\u043e\u043d\u043e\u0441\u0430\u043c\u0435\u043d\u0442.\u041c\u043e\u0434\u0443\u043b\u044c\u041e\u0431\u044a\u0435\u043a\u0442\u0430
\u043f\u043e \u043f\u0440\u0438\u0447\u0438\u043d\u0435:
{\u0421\u043f\u0440\u0430\u0432\u043e\u0447\u043d\u0438\u043a.\u0414\u0440\u0430\u0444\u0442\u043e\u0432\u044b\u0439\u041a\u043e\u043d\u043e\u0441\u0430\u043c\u0435\u043d\u0442.\u041c\u043e\u0434\u0443\u043b\u044c\u041e\u0431\u044a\u0435\u043a\u0442\u0430(464,28)}: \u041f\u0435\u0440\u0435\u043c\u0435\u043d\u043d\u0430\u044f \u043d\u0435 \u043e\u043f\u0440\u0435\u0434\u0435\u043b\u0435\u043d\u0430 (\u0420\u0435\u0436\u0438\u043c\u0414\u0438\u0430\u043b\u043e\u0433\u0430\u0412\u043e\u043f\u0440\u043e\u0441)'
[06/Mar/2017 01:03:32] ERROR [django.request:213] Internal Server Error: /templatedetails/33
Traceback (most recent call last):
  File "/usr/local/lib/python2.7/dist-packages/django/core/handlers/base.py", line 109, in get_response
    response = callback(request, *callback_args, **callback_kwargs)
  File "/usr/local/lib/python2.7/dist-packages/django/views/generic/base.py", line 48, in view
    return self.dispatch(request, *args, **kwargs)
  File "/usr/local/lib/python2.7/dist-packages/django/utils/decorators.py", line 25, in _wrapper
    return bound_func(*args, **kwargs)
  File "/usr/local/lib/python2.7/dist-packages/django/contrib/auth/decorators.py", line 20, in _wrapped_view
    return view_func(request, *args, **kwargs)
  File "/usr/local/lib/python2.7/dist-packages/django/utils/decorators.py", line 21, in bound_func
    return func(self, *args2, **kwargs2)
  File "/home/picasso/git/export/export/nutep/views.py", line 53, in dispatch
    return super(BaseView, self).dispatch(*args, **kwargs)
  File "/usr/local/lib/python2.7/dist-packages/django/views/generic/base.py", line 69, in dispatch
    return handler(request, *args, **kwargs)
  File "/usr/local/lib/python2.7/dist-packages/django/views/generic/base.py", line 123, in get
    context = self.get_context_data(**kwargs)
  File "/home/picasso/git/export/export/nutep/views.py", line 99, in get_context_data
    draft_service.update_status(pk)
  File "/home/picasso/git/export/export/nutep/services.py", line 74, in update_status
    self.parse_response(response, pk)
  File "/home/picasso/git/export/export/nutep/services.py", line 102, in parse_response
    container.save()
  File "/usr/local/lib/python2.7/dist-packages/django/db/models/base.py", line 463, in save
    self.save_base(using=using, force_insert=force_insert, force_update=force_update)
  File "/usr/local/lib/python2.7/dist-packages/django/db/models/base.py", line 551, in save_base
    result = manager._insert([self], fields=fields, return_id=update_pk, using=using, raw=raw)
  File "/usr/local/lib/python2.7/dist-packages/django/db/models/manager.py", line 203, in _insert
    return insert_query(self.model, objs, fields, **kwargs)
  File "/usr/local/lib/python2.7/dist-packages/django/db/models/query.py", line 1593, in insert_query
    return query.get_compiler(using=using).execute_sql(return_id)
  File "/usr/local/lib/python2.7/dist-packages/django/db/models/sql/compiler.py", line 912, in execute_sql
    cursor.execute(sql, params)
  File "/usr/local/lib/python2.7/dist-packages/django/db/backends/util.py", line 49, in execute
    logger.debug('(%.3f) %s; args=%s' % (duration, sql, params),
UnicodeEncodeError: 'ascii' codec can't encode characters in position 0-4: ordinal not in range(128)
[06/Mar/2017 01:08:12] ERROR [django.request:213] Internal Server Error: /templatedetails/33
Traceback (most recent call last):
  File "/usr/local/lib/python2.7/dist-packages/django/core/handlers/base.py", line 109, in get_response
    response = callback(request, *callback_args, **callback_kwargs)
  File "/usr/local/lib/python2.7/dist-packages/django/views/generic/base.py", line 48, in view
    return self.dispatch(request, *args, **kwargs)
  File "/usr/local/lib/python2.7/dist-packages/django/utils/decorators.py", line 25, in _wrapper
    return bound_func(*args, **kwargs)
  File "/usr/local/lib/python2.7/dist-packages/django/contrib/auth/decorators.py", line 20, in _wrapped_view
    return view_func(request, *args, **kwargs)
  File "/usr/local/lib/python2.7/dist-packages/django/utils/decorators.py", line 21, in bound_func
    return func(self, *args2, **kwargs2)
  File "/home/picasso/git/export/export/nutep/views.py", line 53, in dispatch
    return super(BaseView, self).dispatch(*args, **kwargs)
  File "/usr/local/lib/python2.7/dist-packages/django/views/generic/base.py", line 69, in dispatch
    return handler(request, *args, **kwargs)
  File "/usr/local/lib/python2.7/dist-packages/django/views/generic/base.py", line 123, in get
    context = self.get_context_data(**kwargs)
  File "/home/picasso/git/export/export/nutep/views.py", line 99, in get_context_data
    draft_service.update_status(pk)
  File "/home/picasso/git/export/export/nutep/services.py", line 75, in update_status
    self.parse_response(response, pk)
  File "/home/picasso/git/export/export/nutep/services.py", line 103, in parse_response
    container.save()
  File "/usr/local/lib/python2.7/dist-packages/django/db/models/base.py", line 463, in save
    self.save_base(using=using, force_insert=force_insert, force_update=force_update)
  File "/usr/local/lib/python2.7/dist-packages/django/db/models/base.py", line 551, in save_base
    result = manager._insert([self], fields=fields, return_id=update_pk, using=using, raw=raw)
  File "/usr/local/lib/python2.7/dist-packages/django/db/models/manager.py", line 203, in _insert
    return insert_query(self.model, objs, fields, **kwargs)
  File "/usr/local/lib/python2.7/dist-packages/django/db/models/query.py", line 1593, in insert_query
    return query.get_compiler(using=using).execute_sql(return_id)
  File "/usr/local/lib/python2.7/dist-packages/django/db/models/sql/compiler.py", line 912, in execute_sql
    cursor.execute(sql, params)
  File "/usr/local/lib/python2.7/dist-packages/django/db/backends/util.py", line 49, in execute
    logger.debug('(%.3f) %s; args=%s' % (duration, sql, params),
UnicodeEncodeError: 'ascii' codec can't encode characters in position 0-4: ordinal not in range(128)
[06/Mar/2017 01:10:08] ERROR [django.request:213] Internal Server Error: /templatedetails/33
Traceback (most recent call last):
  File "/usr/local/lib/python2.7/dist-packages/django/core/handlers/base.py", line 109, in get_response
    response = callback(request, *callback_args, **callback_kwargs)
  File "/usr/local/lib/python2.7/dist-packages/django/views/generic/base.py", line 48, in view
    return self.dispatch(request, *args, **kwargs)
  File "/usr/local/lib/python2.7/dist-packages/django/utils/decorators.py", line 25, in _wrapper
    return bound_func(*args, **kwargs)
  File "/usr/local/lib/python2.7/dist-packages/django/contrib/auth/decorators.py", line 20, in _wrapped_view
    return view_func(request, *args, **kwargs)
  File "/usr/local/lib/python2.7/dist-packages/django/utils/decorators.py", line 21, in bound_func
    return func(self, *args2, **kwargs2)
  File "/home/picasso/git/export/export/nutep/views.py", line 53, in dispatch
    return super(BaseView, self).dispatch(*args, **kwargs)
  File "/usr/local/lib/python2.7/dist-packages/django/views/generic/base.py", line 69, in dispatch
    return handler(request, *args, **kwargs)
  File "/usr/local/lib/python2.7/dist-packages/django/views/generic/base.py", line 123, in get
    context = self.get_context_data(**kwargs)
  File "/home/picasso/git/export/export/nutep/views.py", line 99, in get_context_data
    draft_service.update_status(pk)
  File "/home/picasso/git/export/export/nutep/services.py", line 75, in update_status
    self.parse_response(response, pk)
  File "/home/picasso/git/export/export/nutep/services.py", line 104, in parse_response
    container.save()
  File "/usr/local/lib/python2.7/dist-packages/django/db/models/base.py", line 463, in save
    self.save_base(using=using, force_insert=force_insert, force_update=force_update)
  File "/usr/local/lib/python2.7/dist-packages/django/db/models/base.py", line 551, in save_base
    result = manager._insert([self], fields=fields, return_id=update_pk, using=using, raw=raw)
  File "/usr/local/lib/python2.7/dist-packages/django/db/models/manager.py", line 203, in _insert
    return insert_query(self.model, objs, fields, **kwargs)
  File "/usr/local/lib/python2.7/dist-packages/django/db/models/query.py", line 1593, in insert_query
    return query.get_compiler(using=using).execute_sql(return_id)
  File "/usr/local/lib/python2.7/dist-packages/django/db/models/sql/compiler.py", line 912, in execute_sql
    cursor.execute(sql, params)
  File "/usr/local/lib/python2.7/dist-packages/django/db/backends/util.py", line 49, in execute
    logger.debug('(%.3f) %s; args=%s' % (duration, sql, params),
UnicodeEncodeError: 'ascii' codec can't encode characters in position 0-4: ordinal not in range(128)
[06/Mar/2017 01:10:54] ERROR [django.request:213] Internal Server Error: /templatedetails/33
Traceback (most recent call last):
  File "/usr/local/lib/python2.7/dist-packages/django/core/handlers/base.py", line 109, in get_response
    response = callback(request, *callback_args, **callback_kwargs)
  File "/usr/local/lib/python2.7/dist-packages/django/views/generic/base.py", line 48, in view
    return self.dispatch(request, *args, **kwargs)
  File "/usr/local/lib/python2.7/dist-packages/django/utils/decorators.py", line 25, in _wrapper
    return bound_func(*args, **kwargs)
  File "/usr/local/lib/python2.7/dist-packages/django/contrib/auth/decorators.py", line 20, in _wrapped_view
    return view_func(request, *args, **kwargs)
  File "/usr/local/lib/python2.7/dist-packages/django/utils/decorators.py", line 21, in bound_func
    return func(self, *args2, **kwargs2)
  File "/home/picasso/git/export/export/nutep/views.py", line 53, in dispatch
    return super(BaseView, self).dispatch(*args, **kwargs)
  File "/usr/local/lib/python2.7/dist-packages/django/views/generic/base.py", line 69, in dispatch
    return handler(request, *args, **kwargs)
  File "/usr/local/lib/python2.7/dist-packages/django/views/generic/base.py", line 123, in get
    context = self.get_context_data(**kwargs)
  File "/home/picasso/git/export/export/nutep/views.py", line 99, in get_context_data
    draft_service.update_status(pk)
  File "/home/picasso/git/export/export/nutep/services.py", line 75, in update_status
    self.parse_response(response, pk)
  File "/home/picasso/git/export/export/nutep/services.py", line 104, in parse_response
    container.save()
  File "/usr/local/lib/python2.7/dist-packages/django/db/models/base.py", line 463, in save
    self.save_base(using=using, force_insert=force_insert, force_update=force_update)
  File "/usr/local/lib/python2.7/dist-packages/django/db/models/base.py", line 551, in save_base
    result = manager._insert([self], fields=fields, return_id=update_pk, using=using, raw=raw)
  File "/usr/local/lib/python2.7/dist-packages/django/db/models/manager.py", line 203, in _insert
    return insert_query(self.model, objs, fields, **kwargs)
  File "/usr/local/lib/python2.7/dist-packages/django/db/models/query.py", line 1593, in insert_query
    return query.get_compiler(using=using).execute_sql(return_id)
  File "/usr/local/lib/python2.7/dist-packages/django/db/models/sql/compiler.py", line 912, in execute_sql
    cursor.execute(sql, params)
  File "/usr/local/lib/python2.7/dist-packages/django/db/backends/util.py", line 40, in execute
    return self.cursor.execute(sql, params)
  File "/usr/local/lib/python2.7/dist-packages/django/db/backends/postgresql_psycopg2/base.py", line 52, in execute
    return self.cursor.execute(query, args)
IntegrityError: null value in column "SOC" violates not-null constraint

